Workbook

Sheet English
A1: STANDARD | B1: Logistics Service Fee Per Order * Rates in IDR, VAT inclusive
B2: Shipping Route # | D2: Parcel Weight Tier (KG) ^
B3: Zone A | C3: Zone B | D3: 0.00 - 1.00 kg | E3: 1.01 - 2.00 kg | F3: 2.01 - 3.00 kg | G3: 3.01 - 4.00 kg | H3: 4.01 - 5.00 kg | I3: > 5.00 kg
B4: Java | C4: Java (Jakarta) | D4: 690 | E4: 890 | F4: 1620 | G4: 2220 | H4: 2730 | I4: 4350
B5: Java | C5: Java (Non-Jakarta) | D5: 990 | E5: 1090 | F5: 2220 | G5: 3030 | H5: 3540 | I5: 5060
B6: Java | C6: Bali | D6: 1720 | E6: 2220 | F6: 4150 | G6: 5060 | H6: 5060 | I6: 5060
B7: Java | C7: Nusa Tenggara | D7: 2930 | E7: 3640 | F7: 5060 | G7: 5060 | H7: 5060 | I7: 5060
B8: Java | C8: Sumatra | D8: 2830 | E8: 3330 | F8: 5060 | G8: 5060 | H8: 5060 | I8: 5060
B9: Java | C9: Sulawesi | D9: 3940 | E9: 4850 | F9: 5060 | G9: 5060 | H9: 5060 | I9: 5060
B10: Java | C10: Kalimantan | D10: 3440 | E10: 4150 | F10: 5060 | G10: 5060 | H10: 5060 | I10: 5060
B11: Java | C11: Papua & Maluku | D11: 5060 | E11: 5060 | F11: 5060 | G11: 5060 | H11: 5060 | I11: 5060
B12: Out Java | C12: Out Java | D12: 2020 | E12: 2530 | F12: 3840 | G12: 4950 | H12: 5060 | I12: 5060
A14: ECONOMY | B14: Logistics Service Fee Per Order * Rates in IDR, VAT inclusive
B15: Shipping Route # | D15: Parcel Weight Tier (KG) ^
B16: Zone A | C16: Zone B | D16: 0.00 - 1.00 kg | E16: 1.01 - 2.00 kg | F16: 2.01 - 3.00 kg | G16: 3.01 - 4.00 kg | H16: 4.01 - 5.00 kg | I16: > 5.00 kg
B17: Java | C17: Java (Jakarta) | D17: N.A. †
B18: Java | C18: Java (Non-Jakarta)
B19: Java | C19: Bali | D19: 1420 | E19: 1920 | F19: 3440 | G19: 4850 | H19: 5060 | I19: 5060
B20: Java | C20: Nusa Tenggara | D20: 2430 | E20: 3030 | F20: 5060 | G20: 5060 | H20: 5060 | I20: 5060
B21: Java | C21: Sumatra | D21: 1920 | E21: 2330 | F21: 3940 | G21: 5060 | H21: 5060 | I21: 5060
B22: Java | C22: Sulawesi | D22: 3540 | E22: 4250 | F22: 5060 | G22: 5060 | H22: 5060 | I22: 5060
B23: Java | C23: Kalimantan | D23: 3130 | E23: 3640 | F23: 5060 | G23: 5060 | H23: 5060 | I23: 5060
B24: Java | C24: Papua & Maluku | D24: 3540 | E24: 4250 | F24: 5060 | G24: 5060 | H24: 5060 | I24: 5060
B25: Out Java | C25: Out Java | D25: 2020 | E25: 2530 | F25: 3840 | G25: 4950 | H25: 5060 | I25: 5060
A27: CARGO | B27: Logistics Service Fee Per Order * Rates in IDR, VAT inclusive
B28: Shipping Route # | D28: Parcel Weight Tier (KG) ^
B29: Zone A | C29: Zone B | D29: 0.00 - 1.00 kg | E29: 1.01 - 2.00 kg | F29: 2.01 - 3.00 kg | G29: 3.01 - 4.00 kg | H29: 4.01 - 5.00 kg | I29: > 5.00 kg
B30: Java | C30: Java (Jakarta) | D30: N.A. † | F30: 1420 | G30: 1520 | H30: 1520 | I30: 4850
B31: Java | C31: Java (Non-Jakarta) | F31: 1420 | G31: 1420 | H31: 1520 | I31: 4550
B32: Java | C32: Bali | F32: 3940 | G32: 4250 | H32: 4350 | I32: 5060
B33: Java | C33: Nusa Tenggara | F33: 5060 | G33: 5060 | H33: 5060 | I33: 5060
B34: Java | C34: Sumatra | F34: 3940 | G34: 4040 | H34: 4150 | I34: 5060
B35: Java | C35: Sulawesi | F35: 5060 | G35: 5060 | H35: 5060 | I35: 5060
B36: Java | C36: Kalimantan | F36: 5060 | G36: 5060 | H36: 5060 | I36: 5060
B37: Java | C37: Papua & Maluku | F37: 5060 | G37: 5060 | H37: 5060 | I37: 5060
B38: Out Java | C38: Out Java | F38: 2930 | G38: 3340 | H38: 3340 | I38: 5060
A40: INSTANT & SAME DAY | B40: Logistics Service Fee Per Order * Rates in IDR, VAT inclusive
B41: Shipment From | C41: All distances (KM)
B42: Java (Jakarta) | C42: 2020
B43: Java (Non-Jakarta) | C43: 3030
...

Sheet Bahasa Indonesia
A1: STANDAR | B1: Biaya Layanan Logistik per Pesanan * Tarif ditampilkan dalam IDR, termasuk PPN
B2: Jalur Pengiriman # | D2: Tingkatan Berat Paket (KG) ^
B3: Zona A | C3: Zona B | D3: 0.00 - 1.00 kg | E3: 1.01 - 2.00 kg | F3: 2.01 - 3.00 kg | G3: 3.01 - 4.00 kg | H3: 4.01 - 5.00 kg | I3: > 5.00 kg
B4: Jawa | C4: Jawa (Jakarta) | D4: =English!D4 -> 690 | E4: =English!E4 -> 890 | F4: =English!F4 -> 1620 | G4: =English!G4 -> 2220 | H4: =English!H4 -> 2730 | I4: =English!I4 -> 4350
B5: Jawa | C5: Jawa (Selain Jakarta) | D5: =English!D5 -> 990 | E5: =English!E5 -> 1090 | F5: =English!F5 -> 2220 | G5: =English!G5 -> 3030 | H5: =English!H5 -> 3540 | I5: =English!I5 -> 5060
B6: Jawa | C6: Bali | D6: =English!D6 -> 1720 | E6: =English!E6 -> 2220 | F6: =English!F6 -> 4150 | G6: =English!G6 -> 5060 | H6: =English!H6 -> 5060 | I6: =English!I6 -> 5060
B7: Jawa | C7: Nusa Tenggara | D7: =English!D7 -> 2930 | E7: =English!E7 -> 3640 | F7: =English!F7 -> 5060 | G7: =English!G7 -> 5060 | H7: =English!H7 -> 5060 | I7: =English!I7 -> 5060
B8: Jawa | C8: Sumatera | D8: =English!D8 -> 2830 | E8: =English!E8 -> 3330 | F8: =English!F8 -> 5060 | G8: =English!G8 -> 5060 | H8: =English!H8 -> 5060 | I8: =English!I8 -> 5060
B9: Jawa | C9: Sulawesi | D9: =English!D9 -> 3940 | E9: =English!E9 -> 4850 | F9: =English!F9 -> 5060 | G9: =English!G9 -> 5060 | H9: =English!H9 -> 5060 | I9: =English!I9 -> 5060
B10: Jawa | C10: Kalimantan | D10: =English!D10 -> 3440 | E10: =English!E10 -> 4150 | F10: =English!F10 -> 5060 | G10: =English!G10 -> 5060 | H10: =English!H10 -> 5060 | I10: =English!I10 -> 5060
B11: Jawa | C11: Papua & Maluku | D11: =English!D11 -> 5060 | E11: =English!E11 -> 5060 | F11: =English!F11 -> 5060 | G11: =English!G11 -> 5060 | H11: =English!H11 -> 5060 | I11: =English!I11 -> 5060
B12: Luar Jawa | C12: Luar Jawa | D12: =English!D12 -> 2020 | E12: =English!E12 -> 2530 | F12: =English!F12 -> 3840 | G12: =English!G12 -> 4950 | H12: =English!H12 -> 5060 | I12: =English!I12 -> 5060
A14: EKONOMI | B14: Biaya Layanan Logistik per Pesanan * Tarif ditampilkan dalam IDR, termasuk PPN
B15: Jalur Pengiriman # | D15: Tingkatan Berat Paket (KG) ^
B16: Zona A | C16: Zona B | D16: 0.00 - 1.00 kg | E16: 1.01 - 2.00 kg | F16: 2.01 - 3.00 kg | G16: 3.01 - 4.00 kg | H16: 4.01 - 5.00 kg | I16: > 5.00 kg
B17: Jawa | C17: Jawa (Jakarta) | D17: N.A. †
B18: Jawa | C18: Jawa (Selain Jakarta)
B19: Jawa | C19: Bali | D19: =English!D19 -> 1420 | E19: =English!E19 -> 1920 | F19: =English!F19 -> 3440 | G19: =English!G19 -> 4850 | H19: =English!H19 -> 5060 | I19: =English!I19 -> 5060
B20: Jawa | C20: Nusa Tenggara | D20: =English!D20 -> 2430 | E20: =English!E20 -> 3030 | F20: =English!F20 -> 5060 | G20: =English!G20 -> 5060 | H20: =English!H20 -> 5060 | I20: =English!I20 -> 5060
B21: Jawa | C21: Sumatera | D21: =English!D21 -> 1920 | E21: =English!E21 -> 2330 | F21: =English!F21 -> 3940 | G21: =English!G21 -> 5060 | H21: =English!H21 -> 5060 | I21: =English!I21 -> 5060
B22: Jawa | C22: Sulawesi | D22: =English!D22 -> 3540 | E22: =English!E22 -> 4250 | F22: =English!F22 -> 5060 | G22: =English!G22 -> 5060 | H22: =English!H22 -> 5060 | I22: =English!I22 -> 5060
B23: Jawa | C23: Kalimantan | D23: =English!D23 -> 3130 | E23: =English!E23 -> 3640 | F23: =English!F23 -> 5060 | G23: =English!G23 -> 5060 | H23: =English!H23 -> 5060 | I23: =English!I23 -> 5060
B24: Jawa | C24: Papua & Maluku | D24: =English!D24 -> 3540 | E24: =English!E24 -> 4250 | F24: =English!F24 -> 5060 | G24: =English!G24 -> 5060 | H24: =English!H24 -> 5060 | I24: =English!I24 -> 5060
B25: Luar Jawa | C25: Luar Jawa | D25: =English!D25 -> 2020 | E25: =English!E25 -> 2530 | F25: =English!F25 -> 3840 | G25: =English!G25 -> 4950 | H25: =English!H25 -> 5060 | I25: =English!I25 -> 5060
A27: KARGO | B27: Biaya Layanan Logistik per Pesanan * Tarif ditampilkan dalam IDR, termasuk PPN
B28: Jalur Pengiriman # | D28: Tingkatan Berat Paket (KG) ^
B29: Zona A | C29: Zona B | D29: 0.00 - 1.00 kg | E29: 1.01 - 2.00 kg | F29: 2.01 - 3.00 kg | G29: 3.01 - 4.00 kg | H29: 4.01 - 5.00 kg | I29: > 5.00 kg
B30: Jawa | C30: Jawa (Jakarta) | D30: N.A. † | F30: =English!F30 -> 1420 | G30: =English!G30 -> 1520 | H30: =English!H30 -> 1520 | I30: =English!I30 -> 4850
B31: Jawa | C31: Jawa (Selain Jakarta) | F31: =English!F31 -> 1420 | G31: =English!G31 -> 1420 | H31: =English!H31 -> 1520 | I31: =English!I31 -> 4550
B32: Jawa | C32: Bali | F32: =English!F32 -> 3940 | G32: =English!G32 -> 4250 | H32: =English!H32 -> 4350 | I32: =English!I32 -> 5060
B33: Jawa | C33: Nusa Tenggara | F33: =English!F33 -> 5060 | G33: =English!G33 -> 5060 | H33: =English!H33 -> 5060 | I33: =English!I33 -> 5060
B34: Jawa | C34: Sumatera | F34: =English!F34 -> 3940 | G34: =English!G34 -> 4040 | H34: =English!H34 -> 4150 | I34: =English!I34 -> 5060
B35: Jawa | C35: Sulawesi | F35: =English!F35 -> 5060 | G35: =English!G35 -> 5060 | H35: =English!H35 -> 5060 | I35: =English!I35 -> 5060
B36: Jawa | C36: Kalimantan | F36: =English!F36 -> 5060 | G36: =English!G36 -> 5060 | H36: =English!H36 -> 5060 | I36: =English!I36 -> 5060
B37: Jawa | C37: Papua & Maluku | F37: =English!F37 -> 5060 | G37: =English!G37 -> 5060 | H37: =English!H37 -> 5060 | I37: =English!I37 -> 5060
B38: Luar Jawa | C38: Luar Jawa | F38: =English!F38 -> 2930 | G38: =English!G38 -> 3340 | H38: =English!H38 -> 3340 | I38: =English!I38 -> 5060
A40: INSTAN DAN SAMEDAY | B40: Biaya Layanan Logistik per Pesanan * Tarif ditampilkan dalam IDR, termasuk PPN
B41: Asal Pengiriman | C41: Semua Jarak (KM)
B42: Jawa (Jakarta) | C42: =English!C42 -> 2020
B43: Jawa (Selain Jakarta) | C43: =English!C43 -> 3030
...
